Workbook

Sheet Config
A1: HOTCOIN 101 — SERIES CONTROL
A3: Series name | B3: Hotcoin 101
A4: Strapline | B4: Money, explained
A5: Episodes planned | B5: 60
A6: Cadence (days between posts) | B6: 1.5
A7: First publish (local, Asia/Shanghai) | B7: 46260.833
A8: Formats rendered | B8: 9:16 (1080x1920) and 16:9 (1920x1080)
A9: Runtime target | B9: 60 to 80 seconds
A10: Frame rate | B10: 30
A11: Audio | B11: None baked in. Music and VO added in CapCut.
A12: Brand green (confirm vs logo) | B12: #00C566
A13: Paper base | B13: #EFE9DC
A14: Ink | B14: #17170F
A15: Display face | B15: Newsreader
A16: UI face | B16: Inter
A17: Mono face | B17: IBM Plex Mono
A19: Blue cells are inputs. Schedule dates recalculate from the first publish date and the cadence.

Sheet Schedule
A1: # | B1: File | C1: Publish (local) | D1: Weekday | E1: Pillar | F1: Title | G1: Hook (cold open) | H1: Beat outline | I1: Key fact to verify | J1: Takeaway | K1: Hotcoin tie-in | L1: X post copy | M1: Formats | N1: Render command | O1: Status
A2: 1 | B2: FILE 001 | C2: =Config!$B$7+(1-1)*Config!$B$6 -> 46260.833 | D2: =TEXT(C2,"ddd") -> Wed | E2: History | F2: A Short History of Investing | G2: Investing is 5,000 years older than the stock market. | H2: Grain loans in Uruk → shared voyages → VOC shares 1602 → the ticker 1867 → screens and 24/7 markets | I2: The Dutch East India Company (1602) was the first company with publicly tradable shares | J2: Every era solved one problem: move capital to someone who can use it and get paid for the risk. | K2: One account covering crypto, tokenized stocks and prediction markets | L2: Investing is 5,000 years older than the stock market. → Grain loans in Uruk → shared voyages → VOC shares 1602 → the ticker 1867 → screens and 24/7 markets Every era solved one problem: move capital to someone who can use it and get paid for the risk. | M2: 9:16 + 16:9 | N2: Build FILE 001 then render a-short-history-of-investing-vertical and a-short-history-of-investing-horizontal | O2: Rendered
A3: 2 | B3: FILE 002 | C3: =Config!$B$7+(2-1)*Config!$B$6 -> 46262.333 | D3: =TEXT(C3,"ddd") -> Fri | E3: Jargon | F3: WAGMI, NGMI and the Rest | G3: Crypto did not invent hype. It just gave it acronyms. | H3: WAGMI → NGMI → what each signals about positioning → why community language moves price | I3: WAGMI spread from crypto Twitter around 2021 and is now standard NFT and trading slang | J3: Slang is sentiment data. Learn to read it as positioning, not personality. | K3: Light logo end card only | L3: Crypto did not invent hype. It just gave it acronyms. → WAGMI → NGMI → what each signals about positioning → why community language moves price Slang is sentiment data. Learn to read it as positioning, not personality. | M3: 9:16 + 16:9 | N3: Build FILE 002 then render wagmi-ngmi-and-the-rest-vertical and wagmi-ngmi-and-the-rest-horizontal | O3: Planned
A4: 3 | B4: FILE 003 | C4: =Config!$B$7+(3-1)*Config!$B$6 -> 46263.833 | D4: =TEXT(C4,"ddd") -> Sat | E4: Trading | F4: What a Candlestick Actually Tells You | G4: A candle is four numbers wearing a costume. | H4: Open, high, low, close → body vs wick → what a long wick means → why timeframe changes the story | I4: Candlestick charting comes from 18th century Japanese rice traders | J4: A candle is a summary, not a signal. Read the timeframe before you read the shape. | K4: Charting available on Hotcoin spot and futures | L4: A candle is four numbers wearing a costume. → Open, high, low, close → body vs wick → what a long wick means → why timeframe changes the story A candle is a summary, not a signal. Read the timeframe before you read the shape. | M4: 9:16 + 16:9 | N4: Build FILE 003 then render what-a-candlestick-actually-tells-you-vertical and what-a-candlestick-actually-tells-you-horizontal | O4: Planned
A5: 4 | B5: FILE 004 | C5: =Config!$B$7+(4-1)*Config!$B$6 -> 46265.333 | D5: =TEXT(C5,"ddd") -> Mon | E5: Crypto | F5: What a Blockchain Actually Is | G5: A blockchain is a spreadsheet nobody is allowed to edit alone. | H5: Ledger → blocks → consensus → why immutability is economic, not magical | I5: Bitcoin's genesis block was mined on 3 January 2009 | J5: A blockchain does not remove trust. It moves trust from a company to a rule set. | K5: Light logo end card only | L5: A blockchain is a spreadsheet nobody is allowed to edit alone. → Ledger → blocks → consensus → why immutability is economic, not magical A blockchain does not remove trust. It moves trust from a company to a rule set. | M5: 9:16 + 16:9 | N5: Build FILE 004 then render what-a-blockchain-actually-is-vertical and what-a-blockchain-actually-is-horizontal | O5: Planned
A6: 5 | B6: FILE 005 | C6: =Config!$B$7+(5-1)*Config!$B$6 -> 46266.833 | D6: =TEXT(C6,"ddd") -> Tue | E6: TradFi | F6: What a Stock Exchange Really Does | G6: An exchange does not sell you shares. It matches you with someone leaving. | H6: Order matching → market makers → why spreads exist → settlement | I6: The NYSE traces to the 1792 Buttonwood Agreement signed by 24 brokers | J6: An exchange sells certainty of execution, not the asset itself. | K6: Same mechanics on Hotcoin spot books | L6: An exchange does not sell you shares. It matches you with someone leaving. → Order matching → market makers → why spreads exist → settlement An exchange sells certainty of execution, not the asset itself. | M6: 9:16 + 16:9 | N6: Build FILE 005 then render what-a-stock-exchange-really-does-vertical and what-a-stock-exchange-really-does-horizontal | O6: Planned
A7: 6 | B7: FILE 006 | C7: =Config!$B$7+(6-1)*Config!$B$6 -> 46268.333 | D7: =TEXT(C7,"ddd") -> Thu | E7: Risk | F7: Position Sizing Beats Prediction | G7: Most traders die of size, not of being wrong. | H7: Win rate vs size → the 1% rule → why one oversized trade erases ten good ones → sizing as the only variable you control | I7: A 50% drawdown requires a 100% gain just to break even | J7: You cannot control whether you are right. You can control how much it costs to be wrong. | K7: Risk controls and position limits on Hotcoin | L7: Most traders die of size, not of being wrong. → Win rate vs size → the 1% rule → why one oversized trade erases ten good ones → sizing as the only variable you control You cannot control whether you are right. You can control how much it costs to be wrong. | M7: 9:16 + 16:9 | N7: Build FILE 006 then render position-sizing-beats-prediction-vertical and position-sizing-beats-prediction-horizontal | O7: Planned
A8: 7 | B8: FILE 007 | C8: =Config!$B$7+(7-1)*Config!$B$6 -> 46269.833 | D8: =TEXT(C8,"ddd") -> Fri | E8: History | F8: The First Bubble Had Tulips In It | G8: In 1637 a single flower bulb cost more than a house. | H8: Tulip mania → forward contracts → the collapse → what actually repeated in later manias | I8: At the peak, rare tulip bulbs traded for several years of a craftsman's wages | J8: Bubbles are not about the asset. They are about the story that justifies the price. | K8: Light logo end card only | L8: In 1637 a single flower bulb cost more than a house. → Tulip mania → forward contracts → the collapse → what actually repeated in later manias Bubbles are not about the asset. They are about the story that justifies the price. | M8: 9:16 + 16:9 | N8: Build FILE 007 then render the-first-bubble-had-tulips-in-it-vertical and the-first-bubble-had-tulips-in-it-horizontal | O8: Planned
A9: 8 | B9: FILE 008 | C9: =Config!$B$7+(8-1)*Config!$B$6 -> 46271.333 | D9: =TEXT(C9,"ddd") -> Sun | E9: Jargon | F9: FUD, FOMO and the Two Moods of the Market | G9: Every market has two emotions and a lot of vocabulary. | H9: FUD → FOMO → why both are trading signals → how to separate news from noise | I9: The 24 to 30 hour window is when most crypto news is fully priced in | J9: FUD and FOMO describe you, not the market. That is what makes them useful. | K9: Light logo end card only | L9: Every market has two emotions and a lot of vocabulary. → FUD → FOMO → why both are trading signals → how to separate news from noise FUD and FOMO describe you, not the market. That is what makes them useful. | M9: 9:16 + 16:9 | N9: Build FILE 008 then render fud-fomo-and-the-two-moods-of-the-market-vertical and fud-fomo-and-the-two-moods-of-the-market-horizontal | O9: Planned
A10: 9 | B10: FILE 009 | C10: =Config!$B$7+(9-1)*Config!$B$6 -> 46272.833 | D10: =TEXT(C10,"ddd") -> Mon | E10: Crypto | F10: Not Your Keys, Not Your Coins | G10: There are only two ways to hold crypto, and both cost something. | H10: Self custody → exchange custody → the real trade-off is operational risk vs counterparty risk → who should use which | I10: Roughly 20% of all bitcoin is estimated to be permanently lost to inaccessible wallets | J10: Custody is a choice between losing your keys and trusting someone else with them. | K10: Hotcoin custody and withdrawal controls | L10: There are only two ways to hold crypto, and both cost something. → Self custody → exchange custody → the real trade-off is operational risk vs counterparty risk → who should use which Custody is a choice between losing your keys and trusting someone else with them. | M10: 9:16 + 16:9 | N10: Build FILE 009 then render not-your-keys-not-your-coins-vertical and not-your-keys-not-your-coins-horizontal | O10: Planned
A11: 10 | B11: FILE 010 | C11: =Config!$B$7+(10-1)*Config!$B$6 -> 46274.333 | D11: =TEXT(C11,"ddd") -> Wed | E11: Trading | F11: Market, Limit and Stop Orders | G11: Three buttons. Most losses come from pressing the wrong one. | H11: Market order → limit order → stop and stop-limit → when each one hurts you | I11: In thin books a market order can fill several percent away from the last price | J11: Order type is a risk decision, not a convenience setting. | K11: All three order types on Hotcoin | L11: Three buttons. Most losses come from pressing the wrong one. → Market order → limit order → stop and stop-limit → when each one hurts you Order type is a risk decision, not a convenience setting. | M11: 9:16 + 16:9 | N11: Build FILE 010 then render market-limit-and-stop-orders-vertical and market-limit-and-stop-orders-horizontal | O11: Planned
A12: 11 | B12: FILE 011 | C12: =Config!$B$7+(11-1)*Config!$B$6 -> 46275.833 | D12: =TEXT(C12,"ddd") -> Thu | E12: TradFi | F12: What an Index Actually Measures | G12: The S&P 500 is not the economy. It is 500 opinions about it. | H12: Index construction → weighting → survivorship → why the index is not the average company | I12: The S&P 500 is market cap weighted, so the largest names dominate its moves | J12: An index is a rule, not a fact. Read the rule before you read the number. | K12: Tokenized equity exposure on Hotcoin | L12: The S&P 500 is not the economy. It is 500 opinions about it. → Index construction → weighting → survivorship → why the index is not the average company An index is a rule, not a fact. Read the rule before you read the number. | M12: 9:16 + 16:9 | N12: Build FILE 011 then render what-an-index-actually-measures-vertical and what-an-index-actually-measures-horizontal | O12: Planned
A13: 12 | B13: FILE 012 | C13: =Config!$B$7+(12-1)*Config!$B$6 -> 46277.333 | D13: =TEXT(C13,"ddd") -> Sat | E13: Risk | F13: Leverage Is a Clock, Not a Multiplier | G13: Leverage does not make you right faster. It makes you early fatally. | H13: Notional vs margin → liquidation price → funding cost → why time is the hidden variable | I13: At 20x leverage a 5% adverse move liquidates the position | J13: Leverage shortens the time your thesis is allowed to take. | K13: Advanced risk controls on Hotcoin futures | L13: Leverage does not make you right faster. It makes you early fatally. → Notional vs margin → liquidation price → funding cost → why time is the hidden variable Leverage shortens the time your thesis is allowed to take. | M13: 9:16 + 16:9 | N13: Build FILE 012 then render leverage-is-a-clock-not-a-multiplier-vertical and leverage-is-a-clock-not-a-multiplier-horizontal | O13: Planned
A14: 13 | B14: FILE 013 | C14: =Config!$B$7+(13-1)*Config!$B$6 -> 46278.833 | D14: =TEXT(C14,"ddd") -> Sun | E14: History | F14: How Paper Money Got Invented Twice | G14: China printed money 700 years before Europe believed in it. | H14: Song dynasty jiaozi → Yuan paper currency → European banknotes → the same inflation lesson twice | I14: China issued the first government-backed paper currency in the 11th century | J14: Paper money is a technology for trust, and trust has always been the scarce part. | K14: Light logo end card only | L14: China printed money 700 years before Europe believed in it. → Song dynasty jiaozi → Yuan paper currency → European banknotes → the same inflation lesson twice Paper money is a technology for trust, and trust has always been the scarce part. | M14: 9:16 + 16:9 | N14: Build FILE 013 then render how-paper-money-got-invented-twice-vertical and how-paper-money-got-invented-twice-horizontal | O14: Planned
A15: 14 | B15: FILE 014 | C15: =Config!$B$7+(14-1)*Config!$B$6 -> 46280.333 | D15: =TEXT(C15,"ddd") -> Tue | E15: Crypto | F15: Stablecoins, Explained | G15: A stablecoin is a promise with a balance sheet behind it. Or not. | H15: Fiat-backed → overcollateralized → algorithmic → why the peg is a claim, not a law | I15: Terra's UST peg failed in May 2022, erasing tens of billions in days | J15: A stablecoin is only as stable as the thing standing behind it. | K15: Stablecoin pairs on Hotcoin | L15: A stablecoin is a promise with a balance sheet behind it. Or not. → Fiat-backed → overcollateralized → algorithmic → why the peg is a claim, not a law A stablecoin is only as stable as the thing standing behind it. | M15: 9:16 + 16:9 | N15: Build FILE 014 then render stablecoins-explained-vertical and stablecoins-explained-horizontal | O15: Planned
A16: 15 | B16: FILE 015 | C16: =Config!$B$7+(15-1)*Config!$B$6 -> 46281.833 | D16: =TEXT(C16,"ddd") -> Wed | E16: Jargon | F16: Whale, Shrimp, Bagholder | G16: The market has a whole zoo and you are probably in it. | H16: Whale → shrimp → bagholder → why the labels describe behaviour, not wealth | I16: On most chains a small number of addresses hold a large majority of supply | J16: The zoo is a way of talking about concentration. Concentration is a risk factor. | K16: Light logo end card only | L16: The market has a whole zoo and you are probably in it. → Whale → shrimp → bagholder → why the labels describe behaviour, not wealth The zoo is a way of talking about concentration. Concentration is a risk factor. | M16: 9:16 + 16:9 | N16: Build FILE 015 then render whale-shrimp-bagholder-vertical and whale-shrimp-bagholder-horizontal | O16: Planned
A17: 16 | B17: FILE 016 | C17: =Config!$B$7+(16-1)*Config!$B$6 -> 46283.333 | D17: =TEXT(C17,"ddd") -> Fri | E17: Trading | F17: Liquidity: Noticed Only When It Is Gone | G17: Price is an opinion. Liquidity decides if you can act on it. | H17: Depth → spread → slippage → why liquidity vanishes exactly when you need it | I17: Order book depth typically thins sharply during high volatility | J17: Liquidity is the difference between a price and a fill. | K17: Deep books and market making on Hotcoin | L17: Price is an opinion. Liquidity decides if you can act on it. → Depth → spread → slippage → why liquidity vanishes exactly when you need it Liquidity is the difference between a price and a fill. | M17: 9:16 + 16:9 | N17: Build FILE 016 then render liquidity-noticed-only-when-it-is-gone-vertical and liquidity-noticed-only-when-it-is-gone-horizontal | O17: Planned
A18: 17 | B18: FILE 017 | C18: =Config!$B$7+(17-1)*Config!$B$6 -> 46284.833 | D18: =TEXT(C18,"ddd") -> Sat | E18: TradFi | F18: Bonds, or Lending to a Government | G18: The most boring asset on earth sets the price of everything else. | H18: Coupon → yield → price and yield move opposite → why the 10 year matters to crypto | I18: Bond prices fall when yields rise, and the relationship is mechanical | J18: The risk-free rate is the gravity every other asset is priced against. | K18: Macro calendar coverage on Hotcoin | L18: The most boring asset on earth sets the price of everything else. → Coupon → yield → price and yield move opposite → why the 10 year matters to crypto The risk-free rate is the gravity every other asset is priced against. | M18: 9:16 + 16:9 | N18: Build FILE 017 then render bonds-or-lending-to-a-government-vertical and bonds-or-lending-to-a-government-horizontal | O18: Planned
A19: 18 | B19: FILE 018 | C19: =Config!$B$7+(18-1)*Config!$B$6 -> 46286.333 | D19: =TEXT(C19,"ddd") -> Mon | E19: Risk | F19: Risk of Ruin: The Maths of Blowing Up | G19: Lose 50% and you need 100% just to get back. | H19: Drawdown maths → sequence of losses → why survival compounds → the practical fix | I19: A 70% drawdown requires a 233% gain to recover | J19: Staying solvent is not conservative. It is the whole strategy. | K19: Risk controls on Hotcoin | L19: Lose 50% and you need 100% just to get back. → Drawdown maths → sequence of losses → why survival compounds → the practical fix Staying solvent is not conservative. It is the whole strategy. | M19: 9:16 + 16:9 | N19: Build FILE 018 then render risk-of-ruin-the-maths-of-blowing-up-vertical and risk-of-ruin-the-maths-of-blowing-up-horizontal | O19: Planned
A20: 19 | B20: FILE 019 | C20: =Config!$B$7+(19-1)*Config!$B$6 -> 46287.833 | D20: =TEXT(C20,"ddd") -> Tue | E20: History | F20: A Market That Started Under a Tree | G20: 24 brokers, one tree, and the beginning of Wall Street. | H20: Buttonwood Agreement 1792 → fixed commissions → the exchange building → the floor's slow death | I20: The Buttonwood Agreement was signed by 24 brokers in New York in 1792 | J20: Every exchange begins as a private agreement about who gets to trade. | K20: Light logo end card only | L20: 24 brokers, one tree, and the beginning of Wall Street. → Buttonwood Agreement 1792 → fixed commissions → the exchange building → the floor's slow death Every exchange begins as a private agreement about who gets to trade. | M20: 9:16 + 16:9 | N20: Build FILE 019 then render a-market-that-started-under-a-tree-vertical and a-market-that-started-under-a-tree-horizontal | O20: Planned
A21: 20 | B21: FILE 020 | C21: =Config!$B$7+(20-1)*Config!$B$6 -> 46289.333 | D21: =TEXT(C21,"ddd") -> Thu | E21: Crypto | F21: Gas, Blockspace and Why Moving Costs Money | G21: You are not paying a bank. You are bidding for space. | H21: Blockspace as a scarce good → auction dynamics → why fees spike → layer 2 relief | I21: Ethereum gas fees are set by demand for limited space in each block | J21: Fees are not a tax. They are an auction you are participating in. | K21: Withdrawal fee structure on Hotcoin | L21: You are not paying a bank. You are bidding for space. → Blockspace as a scarce good → auction dynamics → why fees spike → layer 2 relief Fees are not a tax. They are an auction you are participating in. | M21: 9:16 + 16:9 | N21: Build FILE 020 then render gas-blockspace-and-why-moving-costs-money-vertical and gas-blockspace-and-why-moving-costs-money-horizontal | O21: Planned
A22: 21 | B22: FILE 021 | C22: =Config!$B$7+(21-1)*Config!$B$6 -> 46290.833 | D22: =TEXT(C22,"ddd") -> Fri | E22: Jargon | F22: Ape, Rug, Degen | G22: Some crypto words are jokes. Some are warnings dressed as jokes. | H22: Ape in → rug pull → degen → what each term is actually describing in risk terms | I22: Rug pulls accounted for a large share of crypto scam losses in recent years | J22: When a community jokes about a risk constantly, the risk is real. | K22: Listing and review process at Hotcoin | L22: Some crypto words are jokes. Some are warnings dressed as jokes. → Ape in → rug pull → degen → what each term is actually describing in risk terms When a community jokes about a risk constantly, the risk is real. | M22: 9:16 + 16:9 | N22: Build FILE 021 then render ape-rug-degen-vertical and ape-rug-degen-horizontal | O22: Planned
A23: 22 | B23: FILE 022 | C23: =Config!$B$7+(22-1)*Config!$B$6 -> 46292.333 | D23: =TEXT(C23,"ddd") -> Sun | E23: Trading | F23: Support and Resistance Without the Mysticism | G23: Lines on a chart are not magic. They are memory. | H23: Where levels come from → why they work → why they break → how to use them without worshipping them | I23: Levels matter because participants place orders at round and remembered prices | J23: A level is a place where people previously made decisions. That is all, and it is enough. | K23: Charting tools on Hotcoin | L23: Lines on a chart are not magic. They are memory. → Where levels come from → why they work → why they break → how to use them without worshipping them A level is a place where people previously made decisions. That is all, and it is enough. | M23: 9:16 + 16:9 | N23: Build FILE 022 then render support-and-resistance-without-the-mysticism-vertical and support-and-resistance-without-the-mysticism-horizontal | O23: Planned
A24: 23 | B24: FILE 023 | C24: =Config!$B$7+(23-1)*Config!$B$6 -> 46293.833 | D24: =TEXT(C24,"ddd") -> Mon | E24: TradFi | F24: What a Broker Does With Your Order | G24: Your order does not go straight to the exchange. Not always. | H24: Routing → internalization → payment for order flow → what best execution means | I24: Payment for order flow is banned in some jurisdictions and permitted in others | J24: Know who is on the other side of your order, and how they are paid. | K24: Transparent order routing on Hotcoin | L24: Your order does not go straight to the exchange. Not always. → Routing → internalization → payment for order flow → what best execution means Know who is on the other side of your order, and how they are paid. | M24: 9:16 + 16:9 | N24: Build FILE 023 then render what-a-broker-does-with-your-order-vertical and what-a-broker-does-with-your-order-horizontal | O24: Planned
A25: 24 | B25: FILE 024 | C25: =Config!$B$7+(24-1)*Config!$B$6 -> 46295.333 | D25: =TEXT(C25,"ddd") -> Wed | E25: Risk | F25: Most Portfolios Are One Bet in Disguise | G25: You own eleven things and one risk. | H25: Correlation → factor exposure → why crypto portfolios cluster → practical diversification | I25: Most large-cap altcoins have historically shown high correlation to $BTC | J25: Diversification is about correlated risk, not the number of tickers. | K25: Multi-asset access on Hotcoin | L25: You own eleven things and one risk. → Correlation → factor exposure → why crypto portfolios cluster → practical diversification Diversification is about correlated risk, not the number of tickers. | M25: 9:16 + 16:9 | N25: Build FILE 024 then render most-portfolios-are-one-bet-in-disguise-vertical and most-portfolios-are-one-bet-in-disguise-horizontal | O25: Planned
A26: 25 | B26: FILE 025 | C26: =Config!$B$7+(25-1)*Config!$B$6 -> 46296.833 | D26: =TEXT(C26,"ddd") -> Thu | E26: History | F26: The 1929 Crash Was a Margin Story | G26: Everyone remembers the crash. Few remember it was bought on credit. | H26: Margin buying in the 1920s → the call → forced selling → the reforms that followed | I26: Investors could buy stock with as little as 10% down before 1929 | J26: Leverage does not cause bubbles. It decides how fast they end. | K26: Risk limits on Hotcoin futures | L26: Everyone remembers the crash. Few remember it was bought on credit. → Margin buying in the 1920s → the call → forced selling → the reforms that followed Leverage does not cause bubbles. It decides how fast they end. | M26: 9:16 + 16:9 | N26: Build FILE 025 then render the-1929-crash-was-a-margin-story-vertical and the-1929-crash-was-a-margin-story-horizontal | O26: Planned
A27: 26 | B27: FILE 026 | C27: =Config!$B$7+(26-1)*Config!$B$6 -> 46298.333 | D27: =TEXT(C27,"ddd") -> Sat | E27: Crypto | F27: Proof of Work vs Proof of Stake | G27: Two ways to make lying expensive. | H27: PoW energy cost → PoS capital cost → security assumptions → the real trade-offs | I27: Ethereum moved from proof of work to proof of stake in September 2022 | J27: Both systems buy the same thing: the cost of attacking the network. | K27: Staking products on Hotcoin | L27: Two ways to make lying expensive. → PoW energy cost → PoS capital cost → security assumptions → the real trade-offs Both systems buy the same thing: the cost of attacking the network. | M27: 9:16 + 16:9 | N27: Build FILE 026 then render proof-of-work-vs-proof-of-stake-vertical and proof-of-work-vs-proof-of-stake-horizontal | O27: Planned
A28: 27 | B28: FILE 027 | C28: =Config!$B$7+(27-1)*Config!$B$6 -> 46299.833 | D28: =TEXT(C28,"ddd") -> Sun | E28: Jargon | F28: HODL: The Typo That Became a Strategy | G28: One forum post in 2013 named an entire philosophy. | H28: The original post → why it stuck → holding as a strategy → when it is the wrong one | I28: The word came from a misspelled 'hold' in a December 2013 forum post | J28: Holding is a strategy only when you can say what would change your mind. | K28: Light logo end card only | L28: One forum post in 2013 named an entire philosophy. → The original post → why it stuck → holding as a strategy → when it is the wrong one Holding is a strategy only when you can say what would change your mind. | M28: 9:16 + 16:9 | N28: Build FILE 027 then render hodl-the-typo-that-became-a-strategy-vertical and hodl-the-typo-that-became-a-strategy-horizontal | O28: Planned
A29: 28 | B29: FILE 028 | C29: =Config!$B$7+(28-1)*Config!$B$6 -> 46301.333 | D29: =TEXT(C29,"ddd") -> Tue | E29: Trading | F29: Funding Rates: The Rent on Your Opinion | G29: In perpetual futures, you pay to keep an opinion open. | H29: What funding is → who pays whom → why it flips → reading it as positioning data | I29: Perpetual futures use funding payments to keep the contract near spot price | J29: Funding is the market telling you which side is crowded. | K29: Funding rates visible on Hotcoin futures | L29: In perpetual futures, you pay to keep an opinion open. → What funding is → who pays whom → why it flips → reading it as positioning data Funding is the market telling you which side is crowded. | M29: 9:16 + 16:9 | N29: Build FILE 028 then render funding-rates-the-rent-on-your-opinion-vertical and funding-rates-the-rent-on-your-opinion-horizontal | O29: Planned
A30: 29 | B30: FILE 029 | C30: =Config!$B$7+(29-1)*Config!$B$6 -> 46302.833 | D30: =TEXT(C30,"ddd") -> Wed | E30: TradFi | F30: Dividends and Buybacks | G30: Two ways a company pays you. One is taxed differently. | H30: Dividend mechanics → buyback mechanics → why buybacks grew → what each signals | I30: US buybacks overtook dividends as the main way large firms return cash | J30: Both return cash. Only one asks your permission to be taxed. | K30: Tokenized equity exposure on Hotcoin | L30: Two ways a company pays you. One is taxed differently. → Dividend mechanics → buyback mechanics → why buybacks grew → what each signals Both return cash. Only one asks your permission to be taxed. | M30: 9:16 + 16:9 | N30: Build FILE 029 then render dividends-and-buybacks-vertical and dividends-and-buybacks-horizontal | O30: Planned
A31: 30 | B31: FILE 030 | C31: =Config!$B$7+(30-1)*Config!$B$6 -> 46304.333 | D31: =TEXT(C31,"ddd") -> Fri | E31: Risk | F31: Being Early Costs the Same as Being Wrong | G31: Timing risk is just risk with better excuses. | H31: The thesis was right, the timing was not → margin and time → sizing for duration → the fix | I31: Positions financed with leverage can be liquidated long before a thesis plays out | J31: A correct call you could not hold is indistinguishable from a wrong one. | K31: Spot vs futures choice on Hotcoin | L31: Timing risk is just risk with better excuses. → The thesis was right, the timing was not → margin and time → sizing for duration → the fix A correct call you could not hold is indistinguishable from a wrong one. | M31: 9:16 + 16:9 | N31: Build FILE 030 then render being-early-costs-the-same-as-being-wrong-vertical and being-early-costs-the-same-as-being-wrong-horizontal | O31: Planned
A32: 31 | B32: FILE 031 | C32: =Config!$B$7+(31-1)*Config!$B$6 -> 46305.833 | D32: =TEXT(C32,"ddd") -> Sat | E32: History | F32: The Day Money Stopped Being Gold | G32: In 1971 the dollar quietly stopped being a receipt. | H32: Bretton Woods → the gold window → the Nixon shock → the world of floating currency | I32: The US ended dollar convertibility into gold in August 1971 | J32: Since 1971, money has been a shared agreement rather than a claim on metal. | K32: Light logo end card only | L32: In 1971 the dollar quietly stopped being a receipt. → Bretton Woods → the gold window → the Nixon shock → the world of floating currency Since 1971, money has been a shared agreement rather than a claim on metal. | M32: 9:16 + 16:9 | N32: Build FILE 031 then render the-day-money-stopped-being-gold-vertical and the-day-money-stopped-being-gold-horizontal | O32: Planned
A33: 32 | B33: FILE 032 | C33: =Config!$B$7+(32-1)*Config!$B$6 -> 46307.333 | D33: =TEXT(C33,"ddd") -> Mon | E33: Crypto | F33: How to Read an Order Book | G33: Every price you see is two queues arguing. | H33: Bids and asks → depth → the spread → why the top of book is not the whole story | I33: The visible spread often understates true cost once size is included | J33: The order book is the only honest thing on the screen. | K33: Full depth view on Hotcoin | L33: Every price you see is two queues arguing. → Bids and asks → depth → the spread → why the top of book is not the whole story The order book is the only honest thing on the screen. | M33: 9:16 + 16:9 | N33: Build FILE 032 then render how-to-read-an-order-book-vertical and how-to-read-an-order-book-horizontal | O33: Planned
A34: 33 | B34: FILE 033 | C34: =Config!$B$7+(33-1)*Config!$B$6 -> 46308.833 | D34: =TEXT(C34,"ddd") -> Tue | E34: Jargon | F34: Alpha, Beta and Edge | G34: Three words traders use to ask one question: am I actually good? | H34: Beta as market exposure → alpha as the rest → edge as repeatability → why most alpha is hidden beta | I34: Most retail outperformance in bull markets is beta, not alpha | J34: If it disappears when the market stops rising, it was never alpha. | K34: Copy trading performance data on Hotcoin | L34: Three words traders use to ask one question: am I actually good? → Beta as market exposure → alpha as the rest → edge as repeatability → why most alpha is hidden beta If it disappears when the market stops rising, it was never alpha. | M34: 9:16 + 16:9 | N34: Build FILE 033 then render alpha-beta-and-edge-vertical and alpha-beta-and-edge-horizontal | O34: Planned
A35: 34 | B35: FILE 034 | C35: =Config!$B$7+(34-1)*Config!$B$6 -> 46310.333 | D35: =TEXT(C35,"ddd") -> Thu | E35: Trading | F35: Copy Trading, Explained Honestly | G35: Copying a trader means copying their risk, not just their entries. | H35: How copy trading works → why drawdown matters more than returns → sizing → what to check first | I35: A strategy's maximum drawdown is a better filter than its total return | J35: Copy the risk profile you can survive, not the return you want. | K35: Copy trading with top providers on Hotcoin | L35: Copying a trader means copying their risk, not just their entries. → How copy trading works → why drawdown matters more than returns → sizing → what to check first Copy the risk profile you can survive, not the return you want. | M35: 9:16 + 16:9 | N35: Build FILE 034 then render copy-trading-explained-honestly-vertical and copy-trading-explained-honestly-horizontal | O35: Planned
A36: 35 | B36: FILE 035 | C36: =Config!$B$7+(35-1)*Config!$B$6 -> 46311.833 | D36: =TEXT(C36,"ddd") -> Fri | E36: TradFi | F36: Tokenized Stocks: What You Actually Own | G36: A tokenized share is a claim, and the claim is the product. | H36: The wrapper → the issuer → what rights transfer → what does not | I36: Tokenized equity products give price exposure without traditional share registry ownership | J36: With tokenized assets, read who owes you what before you read the chart. | K36: Tokenized US stocks on Hotcoin | L36: A tokenized share is a claim, and the claim is the product. → The wrapper → the issuer → what rights transfer → what does not With tokenized assets, read who owes you what before you read the chart. | M36: 9:16 + 16:9 | N36: Build FILE 035 then render tokenized-stocks-what-you-actually-own-vertical and tokenized-stocks-what-you-actually-own-horizontal | O36: Planned
A37: 36 | B37: FILE 036 | C37: =Config!$B$7+(36-1)*Config!$B$6 -> 46313.333 | D37: =TEXT(C37,"ddd") -> Sun | E37: Risk | F37: Drawdown Is a Feeling Before It Is a Number | G37: Most people quit a strategy at the exact worst moment. | H37: Drawdown depth → duration → behavioural response → planning for it in advance | I37: Strategy abandonment tends to peak near the trough of a drawdown | J37: Decide what you will do in a drawdown before you are in one. | K37: Risk dashboards on Hotcoin | L37: Most people quit a strategy at the exact worst moment. → Drawdown depth → duration → behavioural response → planning for it in advance Decide what you will do in a drawdown before you are in one. | M37: 9:16 + 16:9 | N37: Build FILE 036 then render drawdown-is-a-feeling-before-it-is-a-number-vertical and drawdown-is-a-feeling-before-it-is-a-number-horizontal | O37: Planned
A38: 37 | B38: FILE 037 | C38: =Config!$B$7+(37-1)*Config!$B$6 -> 46314.833 | D38: =TEXT(C38,"ddd") -> Mon | E38: History | F38: From Ticker Tape to Fibre Optics | G38: Finance has spent 150 years buying milliseconds. | H38: 1867 ticker → telephone → electronic quotes → microwave towers and colocation | I38: The stock ticker was introduced in 1867 and cut news delay from days to minutes | J38: Every generation of market technology sold the same product: less delay. | K38: Matching engine performance at Hotcoin | L38: Finance has spent 150 years buying milliseconds. → 1867 ticker → telephone → electronic quotes → microwave towers and colocation Every generation of market technology sold the same product: less delay. | M38: 9:16 + 16:9 | N38: Build FILE 037 then render from-ticker-tape-to-fibre-optics-vertical and from-ticker-tape-to-fibre-optics-horizontal | O38: Planned
A39: 38 | B39: FILE 038 | C39: =Config!$B$7+(38-1)*Config!$B$6 -> 46316.333 | D39: =TEXT(C39,"ddd") -> Wed | E39: Crypto | F39: Wallets: Hot, Cold and In Between | G39: A wallet does not hold coins. It holds permission. | H39: Keys vs coins → hot wallet → cold wallet → multisig and the practical middle | I39: Crypto wallets store private keys, while balances live on the chain | J39: You are not storing money. You are storing the ability to move it. | K39: Wallet and withdrawal security on Hotcoin | L39: A wallet does not hold coins. It holds permission. → Keys vs coins → hot wallet → cold wallet → multisig and the practical middle You are not storing money. You are storing the ability to move it. | M39: 9:16 + 16:9 | N39: Build FILE 038 then render wallets-hot-cold-and-in-between-vertical and wallets-hot-cold-and-in-between-horizontal | O39: Planned
A40: 39 | B40: FILE 039 | C40: =Config!$B$7+(39-1)*Config!$B$6 -> 46317.833 | D40: =TEXT(C40,"ddd") -> Thu | E40: Jargon | F40: Pump, Dump and Wash Trading | G40: Three old crimes with new vocabulary. | H40: Pump groups → wash trading → fake volume → how to spot manufactured activity | I40: Wash trading inflates reported volume without changing beneficial ownership | J40: If the volume has no order book behind it, the volume is a costume. | K40: Real volume and surveillance at Hotcoin | L40: Three old crimes with new vocabulary. → Pump groups → wash trading → fake volume → how to spot manufactured activity If the volume has no order book behind it, the volume is a costume. | M40: 9:16 + 16:9 | N40: Build FILE 039 then render pump-dump-and-wash-trading-vertical and pump-dump-and-wash-trading-horizontal | O40: Planned
...

Sheet Pillars
A1: SERIES PILLARS
A3: Pillar | B3: What it covers | C3: Tone | D3: Visual devices
A4: History | B4: Where a market mechanism came from and what it solved | C4: Serious, documentary | D4: Archive plates, timelines
A5: Crypto | B5: How crypto infrastructure actually works | C5: Plain, technical, no hype | D5: Diagrams, order books
A6: TradFi | B6: How traditional finance works and why crypto copied it | C6: Analytical | D6: Comparisons, charts
A7: Trading | B7: Mechanics a trader uses on any venue | C7: Practical | D7: Charts, order types
A8: Jargon | B8: Crypto and trading slang decoded | C8: Light, dry humour | D8: Glossary cards
A9: Risk | B9: Position sizing, drawdown, psychology | C9: Direct, slightly blunt | D9: Numbers, stat cards
A11: Count by pillar
A12: History | B12: =COUNTIF(Schedule!$E$2:$E$61,A12) -> 11
A13: Crypto | B13: =COUNTIF(Schedule!$E$2:$E$61,A13) -> 10
A14: TradFi | B14: =COUNTIF(Schedule!$E$2:$E$61,A14) -> 10
A15: Trading | B15: =COUNTIF(Schedule!$E$2:$E$61,A15) -> 10
A16: Jargon | B16: =COUNTIF(Schedule!$E$2:$E$61,A16) -> 10
A17: Risk | B17: =COUNTIF(Schedule!$E$2:$E$61,A17) -> 9

Sheet Commands
A1: HOW TO BRIEF CLAUDE ON THIS SERIES
A2: Copy a line, paste it into the chat, edit the bits in CAPS.
A4: Situation | B4: What to type | C4: Notes
A5: Make the next episode | B5: Build FILE 0NN from the schedule. Render 9:16 and 16:9. | C5: Pulls title, hook, beats and takeaway straight from this sheet.
A6: Make an episode off-schedule | B6: New episode: PILLAR, title TITLE, hook HOOK. Same series style. Render both formats. | C6: Use for reactive or news-pegged episodes.
A7: Change the script only | B7: Rewrite the beats for FILE 0NN: DESCRIBE THE CHANGE. Re-render both formats. | C7: Script lives in one data file per episode, so this is cheap.
A8: Change the look series-wide | B8: Update the series tokens: CHANGE. Re-render FILE 0NN as a check. | C8: Colours, fonts, paper texture and safe areas all live in one tokens file.
A9: Swap in the real logo | B9: Here is the Hotcoin logo file. Wire it into the series chrome. | C9: Drops into public/ and replaces the placeholder mark everywhere.
A10: Add a new scene type | B10: Add a new beat type called NAME that shows DESCRIPTION. | C10: Beat types are reusable across all future episodes.
A11: Preview before rendering | B11: Show me stills of FILE 0NN before you render the video. | C11: Fast. Stills take seconds, a full render takes minutes.
A12: Change the pace | B12: Make FILE 0NN NN seconds total and rebalance the beats. | C12: Each beat has a seconds value in the script.
A13: Batch a week | B13: Build FILE 0NN through FILE 0NN and render all of them in 9:16. | C13: Roughly 6 minutes of render per vertical episode.
A14: Get the post copy | B14: Give me the X, Instagram and LinkedIn copy for FILE 0NN. | C14: Follows the Hotcoin format: cashtags on X, dot keywords on IG, arrows not bullets.
A15: Change the schedule | B15: Shift the series to start on DATE at TIME, cadence N days. | C15: Only the two blue Config cells change, every date recalculates.
A16: Add Chinese | B16: Produce FILE 0NN in Chinese as well. | C16: Needs a CJK font added to the bundle first.

Sheet Style Bible
A1: HOTCOIN 101 — VISUAL RULES
A3: Surface | B3: Archival paper. Warm off-white, live film grain, faint letterpress grid, printer registration marks in the corners.
A4: Ink | B4: Near black text. Nothing pure black, nothing pure white.
A5: Accent | B5: Hotcoin green, used only for: the logo dot, one rule per page, figure numbers, the highlight marker, the progress bar, and up candles.
A6: Type | B6: Newsreader for statements. Inter for explanation. IBM Plex Mono for labels, years and captions.
A7: Chrome | B7: Every frame carries the same header rail (mark, HOTCOIN 101, pillar, file number) and a green progress rule at the bottom. This is what makes episodes recognisable in a feed.
A8: Motion | B8: Ink rise on text, pen draw on illustrations, paper shift between pages. No slides, no zooms, no glow.
A9: Illustration | B9: Procedural line engravings inside a bordered plate with FIG. NN captions. No stock imagery, no 3D, no neon.
A10: Structure | B10: Cold open hook, title card, four to six figure or data beats, one comparison, one stat, takeaway. Always standalone, never references another episode.
A11: Promotion | B11: One Hotcoin line in the closing frame and at most one product mention inside the body. Never a first-person brand voice.
A12: Formats | B12: 9:16 for Reels, TikTok, Shorts and X vertical. 16:9 for YouTube, LinkedIn and X landscape. Same script, layout adapts.
A13: Safe areas | B13: Vertical keeps the top 19% and bottom 25% clear of key text so platform UI never covers it.
A14: Audio | B14: Rendered silent by design. Music bed and optional VO added in CapCut so one render serves several audio variants.
